python-dotenv could not parse statement starting at line 38
python-dotenv could not parse statement starting at line 40
python-dotenv could not parse statement starting at line 41
python-dotenv could not parse statement starting at line 42
python-dotenv could not parse statement starting at line 43
python-dotenv could not parse statement starting at line 44
python-dotenv could not parse statement starting at line 45
python-dotenv could not parse statement starting at line 46
python-dotenv could not parse statement starting at line 48
python-dotenv could not parse statement starting at line 49
python-dotenv could not parse statement starting at line 50
python-dotenv could not parse statement starting at line 51
python-dotenv could not parse statement starting at line 52
python-dotenv could not parse statement starting at line 53
python-dotenv could not parse statement starting at line 54
python-dotenv could not parse statement starting at line 55
Loaded DATABASE_URL: postgresql+psycopg://k3admin:KH%40123456@localhost...
2025-10-31 10:40:05,814 INFO sqlalchemy.engine.Engine select pg_catalog.version()
2025-10-31 10:40:05,814 INFO sqlalchemy.engine.Engine [raw sql] {}
2025-10-31 10:40:05,816 INFO sqlalchemy.engine.Engine select current_schema()
2025-10-31 10:40:05,816 INFO sqlalchemy.engine.Engine [raw sql] {}
2025-10-31 10:40:05,817 INFO sqlalchemy.engine.Engine show standard_conforming_strings
2025-10-31 10:40:05,817 INFO sqlalchemy.engine.Engine [raw sql] {}
2025-10-31 10:40:05,821 INFO sqlalchemy.engine.Engine BEGIN (implicit)
2025-10-31 10:40:05,827 INFO sqlalchemy.engine.Engine SELECT candidates.id AS candidates_id, candidates.first_name AS candidates_first_name, candidates.last_name AS candidates_last_name, candidates.email AS candidates_email, candidates.phone AS candidates_phone, candidates.current_location AS candidates_current_location, candidates.preferred_locations AS candidates_preferred_locations, candidates.open_to_relocation AS candidates_open_to_relocation, candidates.willing_to_travel AS candidates_willing_to_travel, candidates.professional_summary AS candidates_professional_summary, candidates.career_level AS candidates_career_level, candidates.years_of_experience AS candidates_years_of_experience, candidates.availability_status AS candidates_availability_status, candidates.notice_period_days AS candidates_notice_period_days, candidates.current_salary_currency AS candidates_current_salary_currency, candidates.current_salary_amount AS candidates_current_salary_amount, candidates.expected_salary_currency AS candidates_expected_salary_currency, candidates.expected_salary_amount AS candidates_expected_salary_amount, candidates.linkedin_url AS candidates_linkedin_url, candidates.github_url AS candidates_github_url, candidates.portfolio_url AS candidates_portfolio_url, candidates.personal_website AS candidates_personal_website, candidates.created_at AS candidates_created_at, candidates.updated_at AS candidates_updated_at, candidates.last_active_at AS candidates_last_active_at, candidates.status AS candidates_status 
FROM candidates 
 LIMIT %(param_1)s::INTEGER
2025-10-31 10:40:05,827 INFO sqlalchemy.engine.Engine [generated in 0.00030s] {'param_1': 1}
2025-10-31 10:40:05,832 INFO sqlalchemy.engine.Engine ROLLBACK
Traceback (most recent call last):
  File "C:\Users\karim.hassan\ATS\backend\test_years_calculation.py", line 37, in test_years_calculation
    print(f"\u2139\ufe0f Using existing candidate: {candidate.name} (ID: {candidate.id})")
                                          ^^^^^^^^^^^^^^
AttributeError: 'Candidate' object has no attribute 'name'

During handling of the above exception, another exception occurred:

Traceback (most recent call last):
  File "C:\Users\karim.hassan\ATS\backend\test_years_calculation.py", line 88, in <module>
    test_years_calculation()
    ~~~~~~~~~~~~~~~~~~~~~~^^
  File "C:\Users\karim.hassan\ATS\backend\test_years_calculation.py", line 81, in test_years_calculation
    print(f"\u274c Error during test: {e}")
    ~~~~~^^^^^^^^^^^^^^^^^^^^^^^^^^^^^^
  File "C:\Users\karim.hassan\AppData\Local\Programs\Python\Python313\Lib\encodings\cp1256.py", line 19, in encode
    return codecs.charmap_encode(input,self.errors,encoding_table)[0]
           ~~~~~~~~~~~~~~~~~~~~~^^^^^^^^^^^^^^^^^^^^^^^^^^^^^^^^^^
UnicodeEncodeError: 'charmap' codec can't encode character '\u274c' in position 0: character maps to <undefined>
